Workbook

Sheet All
A1: documentID | B1: images | C1: title | D1: desc | E1: warnings | F1: categories | G1: disposals | H1: tr_title | I1: tr_desc | J1: tr_warnings | K1: tr_categories | L1: tr_disposals | M1: en_title | N1: en_desc | O1: en_warnings | P1: en_categories | Q1: en_disposals
A2: H9YyUss4ecpyxbtZiPEK | B2: https://firebasestorage.googleapis.com/v0/b/easy-recycle-app.firebasestorage.app/o/users%2Fo3Wr784unsMIuBcveBaZZyxEt6J2%2Fuploads%2F1733786205657000_0.jpg?alt=media&token=9720250c-1077-4b78-9915-a052b8ae0838 | C2: Abbeizer | D2: Bis zu 30 Kg (Gesamtmenge/ haushaltsübliche Mengen) Ihrer gefährlichen Abfälle täglich können Sie kostenlos auf den Wertstoffhöfen der Region Hannover oder der Deponie Hannover im Sonderabfallzwischenlager abgeben. Größere Mengen können Sie kostenpflichtig an der Sonderannahmestelle auf der Deponie Hannover abgeben. Bitte beachten Sie hierzu die Preisliste für Sonderabfall. Bitte achten Sie bei dem Transport darauf, die Gebinde gut zu kennzeichnen und auf keinen Fall mit anderen Flüssigkeiten zu vermischen. Am sichersten transportieren Sie Sonderabfälle nur dicht verschlossen in den originalen Behältern (Gebinden) sowie aufrecht stehend (z.B in einer Wanne, die Behälter aufrecht hält). | F2: Sonderabfall | G2: Wertstoffhof, Deponie | H2: Rahip | I2: Günlük 30 kg'a kadar (toplam miktar/normal ev miktarı) tehlikeli atıklarınızı Hannover bölgesindeki geri dönüşüm merkezlerine veya Hannover'deki geçici tehlikeli atık depolama tesisindeki atık depolama sahasına ücretsiz olarak teslim edebilirsiniz. Daha büyük miktarları ücret karşılığında Hannover atık depolama sahasındaki özel toplama noktasına teslim edebilirsiniz. Lütfen tehlikeli atık fiyat listesine dikkat edin. Taşıma sırasında lütfen kapların iyi etiketlendiğinden emin olun ve asla başka sıvılarla karıştırmayın. Tehlikeli atığı taşımanın en güvenli yolu, onu yalnızca orijinal kaplarında (konteynerlerde) sıkıca kapalı olarak ve dik bir şekilde (örn. kapları dik tutan bir tepside) ayakta taşımaktır. | K2: Tehlikeli atık | L2: Geri dönüşüm merkezi, depolama sahası | M2: Abbeizer | N2: You can dispose of up to 30 kg (total amount/normal household amounts) of your hazardous waste daily free of charge at the recycling centers in the Hanover region or at the Hanover landfill in the temporary hazardous waste storage facility. Larger amounts can be disposed of at the special collection point at the Hanover landfill for a fee. Please note the price list for hazardous waste. When transporting, please ensure that the containers are clearly labeled and under no circumstances mixed with other liquids. The safest way to transport hazardous waste is to keep it tightly sealed in the original containers (containers) and in an upright position (e.g. in a tub that holds the container upright). | P2: hazardous waste | Q2: recycling center, landfill
A3: 7DGCkjtd5Te9ZknFOABD | B3: https://firebasestorage.googleapis.com/v0/b/easy-recycle-app.firebasestorage.app/o/users%2Fo3Wr784unsMIuBcveBaZZyxEt6J2%2Fuploads%2F1733786228051000_0.jpg?alt=media&token=c008c189-2e4a-44ad-bd3a-651a96ad286e | C3: Abbeizmittel | D3: Bis zu 30 Kg (Gesamtmenge/ haushaltsübliche Mengen) Ihrer gefährlichen Abfälle täglich können Sie kostenlos auf den Wertstoffhöfen der Region Hannover oder der Deponie Hannover im Sonderabfallzwischenlager abgeben. Größere Mengen können Sie kostenpflichtig an der Sonderannahmestelle auf der Deponie Hannover abgeben. Bitte beachten Sie hierzu die Preisliste für Sonderabfall. Bitte achten Sie bei dem Transport darauf, die Gebinde gut zu kennzeichnen und auf keinen Fall mit anderen Flüssigkeiten zu vermischen. Am sichersten transportieren Sie Sonderabfälle nur dicht verschlossen in den originalen Behältern (Gebinden) sowie aufrecht stehend (z.B in einer Wanne, die Behälter aufrecht hält). | F3: Sonderabfall | G3: Wertstoffhof, Deponie | H3: Boya sökücü | I3: Günlük 30 kg'a kadar (toplam miktar/normal ev miktarı) tehlikeli atıklarınızı Hannover bölgesindeki geri dönüşüm merkezlerine veya Hannover'deki geçici tehlikeli atık depolama tesisindeki atık depolama sahasına ücretsiz olarak teslim edebilirsiniz. Daha büyük miktarları ücret karşılığında Hannover atık depolama sahasındaki özel toplama noktasına teslim edebilirsiniz. Lütfen tehlikeli atık fiyat listesine dikkat edin. Taşıma sırasında lütfen kapların iyi etiketlendiğinden emin olun ve asla başka sıvılarla karıştırmayın. Tehlikeli atığı taşımanın en güvenli yolu, onu yalnızca orijinal kaplarında (konteynerlerde) sıkıca kapalı olarak ve dik konumda (örneğin kapları dik tutan bir tepside) taşımaktır. | K3: Tehlikeli atık | L3: Geri dönüşüm merkezi, depolama sahası | M3: paint stripper | N3: You can dispose of up to 30 kg (total amount/normal household amounts) of your hazardous waste daily free of charge at the recycling centers in the Hanover region or at the Hanover landfill in the temporary hazardous waste storage facility. Larger amounts can be disposed of at the special collection point at the Hanover landfill for a fee. Please note the price list for hazardous waste. When transporting, please ensure that the containers are clearly labeled and under no circumstances mixed with other liquids. The safest way to transport hazardous waste is to keep it tightly sealed in the original containers (containers) and in an upright position (e.g. in a tub that holds the container upright). | P3: hazardous waste | Q3: recycling center, landfill
A4: Fjh9KMz5nQcliulip9GT | C4: Abbruchholz | D4: Bis zu 1 m³ (Gesamtmenge/ haushaltsübliche Mengen) Ihrer Holzabfälle täglich können Sie kostenlos auf den Wertstoffhöfen der Region Hannover abgeben. Größere Mengen können Sie kostenpflichtig an den Deponien der Region Hannover abgeben. Bitte beachten Sie hierzu die Preisliste für die Deponieanlieferung. Die Annahmebedingungen unserer Deponien und Wertstoffhöfe finden Sie , (Deponien) und , (Wertstoffhöfe). | E4: kostenpflichtig, KEIN Sperrmüll | F4: Holzabfall | G4: Wertstoffhof | H4: Abbruchholz | I4: Günlük 1 m³'e kadar (toplam miktar/normal ev miktarı) ahşap atıklarınızı Hannover bölgesindeki geri dönüşüm merkezlerine ücretsiz olarak teslim edebilirsiniz. Daha büyük miktarları bir ücret karşılığında Hannover bölgesindeki atık depolama sahalarına atabilirsiniz. Lütfen çöp sahası teslimatı için fiyat listesine dikkat edin. Atık depolama alanlarımız ve geri dönüşüm merkezlerimiz için kabul koşulları , (atık depolama alanları) ve , (geri dönüşüm merkezleri)'de bulunabilir. | J4: ücretli, hacimli atık YOK | K4: Holzabfall | L4: Geri dönüşüm merkezi | M4: Abbruchholz | N4: You can dispose of up to 1 m³ (total amount/normal household amounts) of your wood waste daily free of charge at the recycling centers in the Hanover region. Larger amounts can be disposed of at the landfills in the Hanover region for a fee. Please note the price list for landfill delivery. The acceptance conditions of our landfills and recycling centers can be found at , (landfills) and , (recycling centers). | O4: fee-based, NO bulky waste | P4: Holzabfall | Q4: recycling center
A5: kEw5ezlLgHpDEtLxXVQP | C5: Abdeckfolie (sauber - ohne Farbreste etc.) | F5: Wertstoff | G5: Wertstoffhof, Gelber Sack | H5: Kaplama filmi (temiz - boya kalıntısı vs yok) | K5: Geri dönüştürülebilir malzeme | L5: Geri dönüşüm merkezi, sarı çanta | M5: Covering film (clean - without paint residue etc.) | P5: recyclable material | Q5: recycling center, yellow bag
A6: 4cbHcKoNJNb5lxmPWr33 | C6: Abdeckfolie (verschmutzt, Gewebe, Plane) | F6: Restabfall | G6: Restabfalltonne | H6: Kaplama filmi (kirli, kumaş, branda) | K6: Yeniden düşme | L6: Yeniden yerleştirme | M6: Covering film (dirty, fabric, tarpaulin) | P6: Restabfall | Q6: Restabfalltonne
A7: mcruBrdK5SPqltBBiSHj | C7: Abdeckfolien | D7: Abdeckfolien aus Kunststoff sind aus Polyethylen (PE). Saubere PE-Folien können wiederverwertet werden. Kleine Mengen nehmen die Wertstoffhöfe im Wertstoffsack an. Größere Mengen aus Gewerbe oder Industrie werden ebenfalls von aha in Containern gesammelt. Wenden Sie sich an den Gewerbekundenservice von aha. | F7: Leichtverpackungen | G7: Wertstoffhof, Gelber Sack | H7: Kapak filmleri | I7: Plastik kaplama filmleri polietilenden (PE) yapılmıştır. Temiz PE filmler geri dönüştürülebilir. Geri dönüşüm merkezleri geri dönüşüm torbalarındaki küçük miktarları kabul etmektedir. İşletme veya endüstriden gelen daha büyük miktarlar da aha tarafından kaplarda toplanıyor. aha'nın ticari müşteri hizmetleriyle iletişime geçin. | K7: Hafif ambalaj | L7: Geri dönüşüm merkezi, sarı çanta | M7: covering foils | N7: Plastic covering films are made of polyethylene (PE). Clean PE films can be recycled. Recycling centers accept small quantities in recycling bags. Larger quantities from commercial or industrial use are also collected by aha in containers. Contact aha's commercial customer service. | P7: lightweight packaging | Q7: recycling center, yellow bag
A8: Tl7G2ZzT7LQnUaHMPwKU | C8: Abdeckfolien (Landwirtschaft: Silo-, Stretch-, Wickelfolien etc.) | D8: Abdeckfolien aus Kunststoff sind aus Polyethylen (PE). Saubere PE-Folien können wiederverwertet werden. Kleine Mengen nehmen die Wertstoffhöfe im Wertstoffsack an. Größere Mengen aus Gewerbe oder Industrie werden ebenfalls von aha in Containern gesammelt. Wenden Sie sich an den Gewerbekundenservice von aha. | E8: NICHT in die Wertstofftonne! | F8: Gewerbeabfall | G8: Gewerbeabfall | H8: Kaplama filmleri (tarım: silo, streç, sarma filmleri vb.) | I8: Plastik kaplama filmleri polietilenden (PE) yapılmıştır. Temiz PE filmler geri dönüştürülebilir. Geri dönüşüm merkezleri geri dönüşüm torbalarındaki küçük miktarları kabul etmektedir. İşletme veya endüstriden gelen daha büyük miktarlar da aha tarafından kaplarda toplanıyor. aha'nın ticari müşteri hizmetleriyle iletişime geçin. | J8: Geri dönüşüm kutusunda DEĞİLDİR! | K8: Ticari atık | L8: Ticari atık | M8: Covering films (agriculture: silo, stretch, wrapping films, etc.) | N8: Plastic covering films are made of polyethylene (PE). Clean PE films can be recycled. Small quantities are accepted at recycling centers in recycling bags. Larger quantities from commercial or industrial use are also collected by aha in containers. Contact aha's commercial customer service. | O8: NOT in the recycling bin! | P8: commercial waste | Q8: commercial waste
A9: uBRCwSrFLd9Pkmto3nC0 | C9: Abflussreiniger | D9: Bis zu 30 Kg (Gesamtmenge/ haushaltsübliche Mengen) Ihrer gefährlichen Abfälle täglich können Sie kostenlos auf den Wertstoffhöfen der Region Hannover oder der Deponie Hannover im Sonderabfallzwischenlager abgeben. Größere Mengen können Sie kostenpflichtig an der Sonderannahmestelle auf der Deponie Hannover abgeben. Bitte beachten Sie hierzu die Preisliste für Sonderabfall. Bitte achten Sie bei dem Transport darauf, die Gebinde gut zu kennzeichnen und auf keinen Fall mit anderen Flüssigkeiten zu vermischen. Am sichersten transportieren Sie Sonderabfälle nur dicht verschlossen in den originalen Behältern (Gebinden) sowie aufrecht stehend (z.B in einer Wanne, die Behälter aufrecht hält). | F9: Sonderabfall | G9: Wertstoffhof, Deponie | H9: Drenaj temizleyici | I9: Günlük 30 kg'a kadar (toplam miktar/normal ev miktarı) tehlikeli atıklarınızı Hannover bölgesindeki geri dönüşüm merkezlerine veya Hannover'deki geçici tehlikeli atık depolama tesisindeki atık depolama sahasına ücretsiz olarak teslim edebilirsiniz. Daha büyük miktarları ücret karşılığında Hannover atık depolama sahasındaki özel toplama noktasına teslim edebilirsiniz. Lütfen tehlikeli atık fiyat listesine dikkat edin. Taşıma sırasında lütfen kapların iyi etiketlendiğinden emin olun ve asla başka sıvılarla karıştırmayın. Tehlikeli atığı taşımanın en güvenli yolu, onu yalnızca orijinal kaplarında (konteynerlerde) sıkıca kapalı olarak ve dik bir şekilde (örn. kapları dik tutan bir tepside) ayakta taşımaktır. | K9: Tehlikeli atık | L9: Geri dönüşüm merkezi, depolama sahası | M9: drain cleaner | N9: You can dispose of up to 30 kg (total amount/normal household amounts) of your hazardous waste daily free of charge at the recycling centers in the Hanover region or at the Hanover landfill in the temporary hazardous waste storage facility. Larger amounts can be disposed of at the special collection point at the Hanover landfill for a fee. Please note the price list for hazardous waste. When transporting, please ensure that the containers are clearly labeled and under no circumstances mixed with other liquids. The safest way to transport hazardous waste is to keep it tightly sealed in the original containers (containers) and in an upright position (e.g. in a tub that holds the container upright). | P9: hazardous waste | Q9: recycling center, landfill
A10: IeVNe2z02dRZe2qHbJGH | C10: Abscheideranlage | D10: aha entsorgt in der Region Hannover die Inhalte von Benzin- und Ölabscheidern und von Sand- und Schlammfängen. Im Auftrag von aha führt die Stadtentwässerung Hannover die Reinigung von Abscheideranlagen regionsweit aus. Ansprechpartner bei der Stadtentwässerung Hannover sind Herr Münder und Herr Wagner, Tel: 0511 - 168 - 47440. Bei Abwesenheit nimmt ein Anrufbeantworter die Anfragen auf. Störungsmeldestelle der Stadtentwässerung, Tel: 0511 - 168 - 47377 tagsüber besetzt, oder Tel: 0511 - 168 - 47333, 24 Std. besetzt. | F10: Sonderabfall | G10: Der Zweckverband Abfallwirtschaft Region Hannover (aha) | H10: Ayırıcı sistemi | I10: aha, Hannover bölgesindeki benzin ve yağ ayırıcıların ve kum ve çamur tutucularının içeriğini bertaraf ediyor. Aha adına Hannover Şehir Drenajı bölge genelindeki separatör sistemlerinin temizliğini gerçekleştirmektedir. Hannover Şehir Drenajındaki irtibat kişileri Bay Münder ve Bay Wagner'dir. Tel: 0511 - 168 - 47440. Eğer orada değilseniz, bir telesekreter sorularınızı kaydedecektir. Şehir drenaj arıza raporlama merkezi, Tel: 0511 - 168 - 47377, gün boyunca personel bulunur veya Tel: 0511 - 168 - 47333, günün 24 saati personel bulunur. | K10: Tehlikeli atık | L10: Atık Yönetimi Bölgesi Hannover Derneği (aha) | M10: separator system | N10: aha disposes of the contents of petrol and oil separators and sand and sludge traps in the Hanover region. On behalf of aha, the Hanover city drainage department carries out the cleaning of separator systems throughout the region. Contact persons at the Hanover city drainage department are Mr. Münder and Mr. Wagner, Tel: 0511 - 168 - 47440. If you are not available, an answering machine will take your enquiries. The city drainage department's fault reporting center, Tel: 0511 - 168 - 47377, manned during the day, or Tel: 0511 - 168 - 47333, manned 24 hours. | P10: hazardous waste | Q10: The Hannover Region Waste Management Association (aha)
A11: ewO50e32XAXt8Wde9wZD | C11: Abschminkpads | E11: nicht in die Kanalisation! | F11: Restabfall, Hygieneabfall | G11: Restabfalltonne | H11: Makyaj temizleme pedleri | J11: kanalizasyona değil! | K11: Yeniden kurulum, Hijyen kurulumu | L11: Yeniden yerleştirme | M11: makeup removal pads | O11: not into the sewer system! | P11: Restabfall, Hygieneabfall | Q11: Restabfalltonne
A12: eCf0HlSPFnB9mcRfMmfP | C12: Abschminktücher | E12: nicht in die Kanalisation! | F12: Restabfall, Hygieneabfall | G12: Restabfalltonne | H12: Makyaj temizleme mendilleri | J12: kanalizasyon sistemine değil! | K12: Yeniden kurulum, Hijyen kurulumu | L12: Yeniden yerleştirme | M12: makeup remover wipes | O12: not into the sewer system! | P12: Restabfall, Hygieneabfall | Q12: Restabfalltonne
A13: hDEubKz42LcbbHjYmhvk | B13: https://storage.googleapis.com/easy-recycle-app.firebasestorage.app/images/47.jpg | C13: Absperrband | F13: Wertstoff | G13: Wertstoffhof, Gelber Sack | H13: Bariyer bandı | K13: Geri dönüştürülebilir malzeme | L13: Geri dönüşüm merkezi, sarı çanta | M13: barrier tape | P13: recyclable material | Q13: recycling center, yellow bag
A14: lYzpziWuzKIY31NRHWBr | C14: Abtönfarbe (Eingetrocknete oder eingedickte) | D14: Binderfarben sind wasserlöslich und zählen nicht zu den gefährlichen Abfällen, verursachen uneingedickt allerding böse Flecken. Eingetrocknete oder eingedickte (mit Sand, Gips oder Sägespäne vermischte Binderfarbe) können dem Restabfall zugeführt werden. Flüssige Binderfarben geben Sie bitte an den Wertstoffhöfen der Region Hannover oder der Deponie Hannover im Sonderabfallzwischenlager ab. | F14: Restabfall | G14: Restabfalltonne | H14: Renk tonu (kurutulmuş veya kalınlaştırılmış) | I14: Bağlayıcı boyalar suda çözünür ve tehlikeli atık olarak sınıflandırılmaz, ancak kalınlaştırılmadan bırakılırsa kötü lekelere neden olurlar. Kurutulmuş veya kalınlaştırılmış bağlayıcı boya (kum, alçı veya talaşla karıştırılmış) artık atık olarak bertaraf edilebilir. Lütfen sıvı bağlayıcı boyaları Hannover bölgesindeki geri dönüşüm merkezlerine veya Hannover atık depolama sahasındaki geçici tehlikeli atık depolama tesisine teslim edin. | K14: Yeniden düşme | L14: Yeniden yerleştirme | M14: tinting paint (dried or thickened) | N14: Binder paints are water-soluble and are not classified as hazardous waste, but if not thickened they cause unpleasant stains. Dried or thickened binder paints (mixed with sand, plaster or sawdust) can be disposed of as residual waste. Please dispose of liquid binder paints at the recycling centers in the Hanover region or at the Hanover landfill in the interim storage facility for hazardous waste. | P14: Restabfall | Q14: Restabfalltonne
A15: uMIzAIf15Slkd0J2uQjW | C15: Abtönfarbe (Flüssige) | D15: Binderfarben sind wasserlöslich und zählen nicht zu den gefährlichen Abfällen, verursachen uneingedickt allerding böse Flecken. Eingetrocknete oder eingedickte (mit Sand, Gips oder Sägespäne vermischte Binderfarbe) können dem Restabfall zugeführt werden. Flüssige Binderfarben geben Sie bitte an den Wertstoffhöfen der Region Hannover oder der Deponie Hannover im Sonderabfallzwischenlager ab. | F15: Sonderabfall, Wertstoff | G15: Wertstoffhof, Deponie | H15: Renklendirme boyası (sıvı) | I15: Bağlayıcı boyalar suda çözünür ve tehlikeli atık olarak sınıflandırılmaz, ancak kalınlaştırılmadan bırakılırsa kötü lekelere neden olurlar. Kurutulmuş veya kalınlaştırılmış bağlayıcı boya (kum, alçı veya talaşla karıştırılmış) artık atık olarak bertaraf edilebilir. Lütfen sıvı bağlayıcı boyaları Hannover bölgesindeki geri dönüşüm merkezlerine veya Hannover atık depolama sahasındaki geçici tehlikeli atık depolama tesisine teslim edin. | K15: Tehlikeli atık, geri dönüştürülebilir malzeme | L15: Geri dönüşüm merkezi, depolama sahası | M15: tinting color (liquid) | N15: Binder paints are water-soluble and are not classified as hazardous waste, but if not thickened they cause unpleasant stains. Dried or thickened binder paints (mixed with sand, plaster or sawdust) can be disposed of as residual waste. Please dispose of liquid binder paints at the recycling centers in the Hanover region or at the Hanover landfill in the interim storage facility for hazardous waste. | P15: hazardous waste, recyclable material | Q15: recycling center, landfill
A16: SeQDa3p6YX7pUruBaPkX | C16: Aceton | D16: Bis zu 30 Kg (Gesamtmenge/ haushaltsübliche Mengen) Ihrer gefährlichen Abfälle täglich können Sie kostenlos auf den Wertstoffhöfen der Region Hannover oder der Deponie Hannover im Sonderabfallzwischenlager abgeben. Größere Mengen können Sie kostenpflichtig an der Sonderannahmestelle auf der Deponie Hannover abgeben. Bitte beachten Sie hierzu die Preisliste für Sonderabfall. Bitte achten Sie bei dem Transport darauf, die Gebinde gut zu kennzeichnen und auf keinen Fall mit anderen Flüssigkeiten zu vermischen. Am sichersten transportieren Sie Sonderabfälle nur dicht verschlossen in den originalen Behältern (Gebinden) sowie aufrecht stehend (z.B in einer Wanne, die Behälter aufrecht hält). | F16: Sonderabfall | G16: Wertstoffhof, Deponie | H16: Aseton | I16: Günlük 30 kg'a kadar (toplam miktar/normal ev miktarı) tehlikeli atıklarınızı Hannover bölgesindeki geri dönüşüm merkezlerine veya Hannover'deki geçici tehlikeli atık depolama tesisindeki atık depolama sahasına ücretsiz olarak teslim edebilirsiniz. Daha büyük miktarları ücret karşılığında Hannover atık depolama sahasındaki özel toplama noktasına teslim edebilirsiniz. Lütfen tehlikeli atık fiyat listesine dikkat edin. Taşıma sırasında lütfen kapların iyi etiketlendiğinden emin olun ve asla başka sıvılarla karıştırmayın. Tehlikeli atığı taşımanın en güvenli yolu, onu yalnızca orijinal kaplarında (konteynerlerde) sıkıca kapalı olarak ve dik bir şekilde (örn. kapları dik tutan bir tepside) ayakta taşımaktır. | K16: Tehlikeli atık | L16: Geri dönüşüm merkezi, depolama sahası | M16: Acetone | N16: You can dispose of up to 30 kg (total amount/normal household amounts) of your hazardous waste daily free of charge at the recycling centers in the Hanover region or at the Hanover landfill in the temporary hazardous waste storage facility. Larger amounts can be disposed of at the special collection point at the Hanover landfill for a fee. Please note the price list for hazardous waste. When transporting, please ensure that the containers are clearly labeled and under no circumstances mixed with other liquids. The safest way to transport hazardous waste is to keep it tightly sealed in the original containers (containers) and in an upright position (e.g. in a tub that holds the container upright). | P16: hazardous waste | Q16: recycling center, landfill
A17: OTiwRc8zw8qgnIAbwd6a | C17: Acetondose (leer - Deckel ablassen) | F17: Wertstoff | G17: Wertstoffhof, Gelber Sack | H17: Aseton kutusu (boş - kapağını açık bırakın) | K17: Geri dönüştürülebilir malzeme | L17: Geri dönüşüm merkezi, sarı çanta | M17: Acetone can (empty - remove lid) | P17: recyclable material | Q17: recycling center, yellow bag
A18: vI27UXBBFDvxaZEYpZWq | C18: Acrylbadewanne | F18: Bauabfall | G18: Deponie | H18: Akrilik küvet | K18: Baufall'da | L18: Depolama sahası | M18: acrylic bathtub | P18: Bauabfall | Q18: landfill
A19: x6UHwOqsAXvKso91hgs5 | C19: Acrylfarbe | F19: Sonderabfall | G19: Wertstoffhof, Deponie | H19: Akrilik boya | K19: Tehlikeli atık | L19: Geri dönüşüm merkezi, depolama sahası | M19: acrylic paint | P19: hazardous waste | Q19: recycling center, landfill
A20: mst4zqVgJas9rllqpawd | C20: Acrylfarbe (ausgehärtet) | F20: Restabfall | G20: Restabfalltonne | H20: Akrilik boya (kürlenmiş) | K20: Yeniden düşme | L20: Yeniden yerleştirme | M20: acrylic paint (cured) | P20: Restabfall | Q20: Restabfalltonne
A21: GGj2c25xxJcaSuY60zXP | C21: Acrylglas, Stegplatten, Plexiglas® | E21: In Kleinmengen Restabfall | F21: Bauabfall | G21: Deponie | H21: Akrilik cam, çok duvarlı levhalar, Plexiglas® | J21: Az miktarda artık atık | K21: Baufall'da | L21: Depolama sahası | M21: acrylic glass, multi-wall sheets, Plexiglas® | O21: In small quantities of residual waste | P21: Bauabfall | Q21: landfill
A22: OinsSn6PrE6Q7xDcHCRF | C22: Adapter, Stecker | F22: Elektrogeräte | G22: Wertstoffhof | H22: Adaptör, fiş | K22: Elektrikli ev aletleri | L22: Geri dönüşüm merkezi | M22: adapter, plug | P22: electrical appliances | Q22: recycling center
A23: iTcDnGQ2BnChxUuL1Sm7 | C23: Adventsbeleuchtung | E23: ACHTUNG enthaltene Akkus/Batterien entfernen | F23: Elektrogeräte | G23: Wertstoffhof | H23: Noel aydınlatması | J23: DİKKAT birlikte verilen şarj edilebilir pilleri/pilleri çıkarın | K23: Elektrikli ev aletleri | L23: Geri dönüşüm merkezi | M23: Advent lighting | O23: ATTENTION: Remove any batteries | P23: electrical appliances | Q23: recycling center
A24: vrphJXRM79aYrpmVYlVK | C24: Adventskalender (bitte in Kunststoff und Pappe trennen) | F24: Wertstoff, Papier | G24: Wertstoffhof, Papiertonne, Papiersack | H24: Advent takvimi (lütfen plastik ve kartonu ayırın) | K24: Geri dönüştürülebilir malzeme, kağıt | L24: Geri dönüşüm merkezi, kağıt kutusu, kağıt torba | M24: Advent calendar (please separate into plastic and cardboard) | P24: recyclable material, paper | Q24: recycling center, paper bin, paper bag
A25: mDQRJlSyBZvY4IoknH2f | C25: Adventskerze | F25: Restabfall | G25: Restabfalltonne | H25: Macera Oyunları | K25: Yeniden düşme | L25: Yeniden yerleştirme | M25: Adventskerze | P25: Restabfall | Q25: Restabfalltonne
A26: 2LFzCWVhZp6F6msxnOxm | C26: Adventskranz (komplett mit Schaumkern, Draht usw.) | F26: Restabfall | G26: Restabfalltonne | H26: Advent çelengi (köpük çekirdek, tel vb. ile birlikte) | K26: Yeniden düşme | L26: Yeniden yerleştirme | M26: Advent wreath (complete with foam core, wire, etc.) | P26: Restabfall | Q26: Restabfalltonne
A27: LCUEdVfWurG0C5ZOzfVA | C27: Adventszweige (ohne Schmuck, Anhaftungen) | F27: Bioabfall | G27: Biotonne, Biosack | H27: Advent dalları (dekorasyonlar ve eklentiler olmadan) | K27: Biyolojik çöküş | L27: Organik çöp kutusu, organik çanta | M27: Advent branches (without decorations, attachments) | P27: Bioabfall | Q27: organic waste bin, organic waste bag
A28: fb8GfSLF8HMe5hw6Onra | C28: Aerosol-Spraydosen (drucklos) | F28: Wertstoff | G28: Wertstoffhof, Gelber Sack | H28: Aerosol sprey kutuları (basınçsız) | K28: Geri dönüştürülebilir malzeme | L28: Geri dönüşüm merkezi, sarı çanta | M28: aerosol spray cans (non-pressurized) | P28: recyclable material | Q28: recycling center, yellow bag
A29: QavqTXSIpASwiS3EV5LS | C29: Aerosol-Spraydosen (mit Inhalt) | F29: Sonderabfall | G29: Wertstoffhof, Deponie | H29: Aerosol sprey kutuları (içerikle birlikte) | K29: Tehlikeli atık | L29: Geri dönüşüm merkezi, depolama sahası | M29: aerosol spray cans (with contents) | P29: hazardous waste | Q29: recycling center, landfill
A30: VT4t5aoFORc834EYtNbz | C30: Agrarfolien (Landwirtschaft: Silo-, Stretch-, Wickelfolien etc..) | E30: NICHT in die Wertstofftonne! | F30: Gewerbeabfall | G30: Gewerbeabfall | H30: Tarımsal filmler (tarım: silo, streç, sarma filmleri vb.) | J30: Geri dönüşüm kutusunda DEĞİLDİR! | K30: Ticari atık | L30: Ticari atık | M30: Agricultural films (agriculture: silo, stretch, wrapping films, etc.) | O30: NOT in the recycling bin! | P30: commercial waste | Q30: commercial waste
A31: oD0mhKdRQUm2L2Xl70Kb | C31: Akkumulatoren (Akkus) | D31: aha nimmt Gerätebatterien, z. B. aus Taschenlampen, Uhren, Radios usw. an. Bis zu 30 kg Ihrer gefährlichen Abfälle täglich können Sie kostenlos auf den Wertstoffhöfen der Region Hannover oder der Deponie Hannover im Sonderabfallzwischenlager abgeben. Ausgediente Akkus von E-Bikes und E-Scootern gehören zu laut §8 Batteriegesetz zu den Industriebatterien. Industriebatterien werden von aha nicht angenommen. Bitte geben Sie diese an den Fachhandel zurück. Die einzige Ausnahme von dieser Regel stellen Starterbatterien auf Bleibasis von LKWs und PKWs sowie Motorrädern dar. Ausgediente Akkus von E-Bikes, E-Scootern und Motorrädern gehören zu laut §8 Batteriegesetz zu den Industriebatterien. Industriebatterien werden von aha nicht angenommen. Bitte geben Sie diese an den Fachhandel zurück. | F31: Sonderabfall | G31: Wertstoffhof, Deponie | H31: Akümülatörler (şarj edilebilir piller) | I31: aha cihazın pillerini alır, ör. B. el fenerlerinden, saatlerden, radyolardan vb. Günde 30 kg'a kadar tehlikeli atıklarınızı Hannover bölgesindeki geri dönüşüm merkezlerine veya Hannover'deki geçici tehlikeli atık depolama tesisindeki atık depolama sahasına ücretsiz olarak teslim edebilirsiniz. Pil Yasası'nın 8. Maddesine göre, e-bisiklet ve e-scooter'ların kullanılmış pilleri endüstriyel pillerdir. aha endüstriyel pilleri kabul etmemektedir. Lütfen bunları yetkili satıcıya iade edin. Bu kuralın tek istisnası kamyonlar, arabalar ve motosikletler için kurşun bazlı marş aküleridir. E-bisikletler, e-scooterlar ve motosikletlerde kullanılan kullanılmış aküler, Pil Yasasının 8. Maddesine göre endüstriyel piller olarak sınıflandırılır. aha endüstriyel pilleri kabul etmemektedir. Lütfen bunları yetkili satıcıya iade edin. | K31: Tehlikeli atık | L31: Geri dönüşüm merkezi, depolama sahası | M31: accumulators (batteries) | N31: aha accepts device batteries, e.g. from flashlights, watches, radios, etc. You can dispose of up to 30 kg of your hazardous waste daily free of charge at the recycling centers in the Hanover region or at the Hanover landfill in the special waste interim storage facility. According to Section 8 of the Battery Act, used batteries from e-bikes and e-scooters are classified as industrial batteries. Industrial batteries are not accepted by aha. Please return them to the specialist retailer. The only exception to this rule are lead-based starter batteries from trucks and cars as well as motorcycles. According to Section 8 of the Battery Act, used batteries from e-bikes, e-scooters and motorcycles are classified as industrial batteries. Industrial batteries are not accepted by aha. Please return them to the specialist retailer. | P31: hazardous waste | Q31: recycling center, landfill
A32: xaauI2vCQg3yU98pHIhv | C32: Akku-Schrauber | E32: ACHTUNG enthaltene Akkus/Batterien entfernen | F32: Elektrogeräte | G32: Wertstoffhof | H32: Akülü tornavida | J32: DİKKAT birlikte verilen şarj edilebilir pilleri/pilleri çıkarın | K32: Elektrikli ev aletleri | L32: Geri dönüşüm merkezi | M32: cordless screwdriver | O32: ATTENTION: Remove any batteries | P32: electrical appliances | Q32: recycling center
A33: coqy3nFHtop7X8CYfaA9 | C33: Akten, Datenrelevante Papiere | D33: Altpapier Die Papierschnipsel bitte in einer Papiertüte sammeln, beim Entleerungsvorgang der Altpapiertonne wehen lose Papierschnipsel häufig heraus. | E33: Persönliche Daten schützen! | F33: Papier | G33: Fachverwerter, Papiertonne, Papiersack | H33: Dosyalar, verilerle ilgili belgeler | I33: Atık kağıt Lütfen kağıt parçalarını bir kese kağıdı içinde toplayın; gevşek kağıt parçaları genellikle atık kağıt kutusu boşaltıldığında havaya uçar. | J33: Kişisel verileri koruyun! | K33: Kağıt | L33: Uzman geri dönüşümcü, kağıt kutusu, kağıt torba | M33: files, data-relevant papers | N33: Waste paper Please collect the paper scraps in a paper bag; when emptying the waste paper bin, loose paper scraps often blow out. | O33: Protect personal data! | P33: Paper | Q33: specialist recycler, paper bin, paper bag
A34: e7UftQ0wVHLlcnAWrZOV | C34: Aktenordner (Karton/Pappe) | D34: Ein Metallbügel stellt kein Problem dar. | F34: Papier | G34: Papiertonne, Papiersack | H34: Dosya klasörü (karton/karton) | I34: Metal bir braket sorun değildir. | K34: Kağıt | L34: Kağıt kutusu, kağıt çuval | M34: file folder (cardboard) | N34: A metal bracket is not a problem. | P34: Paper | Q34: paper bin, paper bag
A35: plYztTv7LKBshSp3ZqFk | C35: Aktenordner (Komplette) | D35: Alte Akten können (soweit es der Datenschutz es erfordert) durch spezielle Aktenvernichtungsfirmen entsorgt bzw. der Verwertung zugeführt werden. Aktendeckel aus Papier/Karton (unbeschichtet) gehören nur ohne Metallinlett in die Papiersammlung. Komplette Ordner ohne Inhalt gehören in den Restabfall. | F35: Restabfall | G35: Restabfalltonne | H35: Dosya klasörü (tamamlandı) | I35: Eski dosyalar (veri koruması gerektiriyorsa) özel belge imha şirketleri tarafından imha edilebilir veya geri dönüştürülebilir. Kağıt/kartondan (kaplamasız) yapılmış dosya kapakları yalnızca metal astarsız kağıt koleksiyonuna aittir. İçeriği olmayan komple klasörler artık atık kapsamına girer. | K35: Yeniden düşme | L35: Yeniden yerleştirme | M35: File Folder (Complete) | N35: Old files can be disposed of or recycled by special document destruction companies (if data protection requires it). File covers made of paper/cardboard (uncoated) only belong in the paper collection without a metal insert. Complete folders without contents belong in the residual waste. | P35: Restabfall | Q35: Restabfalltonne
A36: AMRn8cNrSvHoxYA9lUra | C36: Aktenordner (Kunststoff/Papier Mix) | D36: Restabfall Alles was in Säcke paßt ist kostenpflichtig. | F36: Restabfall | G36: Restabfalltonne | H36: Dosya klasörü (plastik/kağıt karışımı) | I36: Artık atık Torbalara sığan her şey ücrete tabidir. | K36: Yeniden düşme | L36: Yeniden yerleştirme | M36: file folder (plastic/paper mix) | N36: Residual waste Everything that fits in bags is subject to a fee. | P36: Restabfall | Q36: Restabfalltonne
A37: eqgPHWXnG8k5DmZM0oXY | C37: Aktenordner (Papier/Karton) | D37: Alte Akten können (soweit es der Datenschutz es erfordert) durch spezielle Aktenvernichtungsfirmen entsorgt bzw. der Verwertung zugeführt werden. Aktendeckel aus Papier/Karton (unbeschichtet) gehören nur ohne Metallinlett in die Papiersammlung. Komplette Ordner ohne Inhalt gehören in den Restabfall. | F37: Papier | G37: Papiertonne, Papiersack | H37: Dosya klasörleri (kağıt/karton) | I37: Eski dosyalar, özel belge imha şirketleri tarafından imha edilebilir veya geri dönüştürülebilir (veri koruması gerektiriyorsa). Kağıt/kartondan (kaplamasız) yapılmış dosya kapakları yalnızca metal astarı olmayan kağıt koleksiyonuna aittir. İçeriği olmayan komple klasörler artık atık kapsamına girer. | K37: Kağıt | L37: Kağıt kutusu, kağıt çuval | M37: file folders (paper/cardboard) | N37: Old files can be disposed of or recycled by special document destruction companies (if data protection requires it). File covers made of paper/cardboard (uncoated) only belong in the paper collection without a metal insert. Complete folders without contents belong in the residual waste. | P37: Paper | Q37: paper bin, paper bag
A38: XTR2wPNmQwIWXxnk9asu | C38: Aktenordner/Hefter (Kunststoff (ohne Pappe)) | F38: Wertstoff | G38: Wertstoffhof, Gelber Sack | H38: Dosya klasörü/zımbalayıcı (plastik (kartonsuz)) | K38: Geri dönüştürülebilir malzeme | L38: Geri dönüşüm merkezi, sarı çanta | M38: File folder/stapler (plastic (without cardboard)) | P38: recyclable material | Q38: recycling center, yellow bag
A39: y8D4lzJ6i9AMUkmdMzaa | C39: Aktenvernichter | F39: Elektrogeräte | G39: Wertstoffhof | H39: Kağıt parçalayıcı | K39: Elektrikli ev aletleri | L39: Geri dönüşüm merkezi | M39: document shredder | P39: electrical appliances | Q39: recycling center
A40: DCs2IHx8ii44FItt7EpJ | C40: Aktivkohlefilter | D40: Alles was in Säcke passt ist kostenpflichtig. Nur ohne Schadstoffbelastung aus der privaten Nutzung | F40: Restabfall | G40: Restabfalltonne | H40: Aktif karbon filtresi | I40: Çantalara sığan her şey ücretlidir. Sadece özel kullanımdan kaynaklanan kirlilik olmadan | K40: Yeniden düşme | L40: Yeniden yerleştirme | M40: activated carbon filter | N40: Everything that fits in bags is subject to a fee. Only without pollutants from private use | P40: Restabfall | Q40: Restabfalltonne
...

Sheet Hannover
A1: title | B1: categories | C1: disposal | D1: descriptions | E1: desc2 | F1: category2 | G1: disp2 | H1: desc_test | I1: cat_test | J1: disp_test | K1: status
A2: Abbeizmittel | B2: Sonderabfall | C2: Wertstoffhof,Deponie Hannover - Sonderabfallannahmestelle | D2: Bis zu 30kg (Gesamtmenge/ haushaltsübliche Mengen) Ihrer gefährlichen Abfälle, können Sie täglich kostenlos auf allen Wertstoffhöfen abgeben. Auf den Wertstoffhöfen der Region werden Sonderabfälle in Gebinden bis zu einer Größe von max. 10 Litern entgegengenommen. Größere Mengen oder Gebinde können kostenpflichtig an der Sonderannahmestelle auf der Deponie Hannover Lahe abgeben. Gebinde über 10 Liter sind ebenfalls an der Deponie in Hannover anzuliefern.,Bitte beachten Sie die Mengenbegrenzung der einzelnen Abfälle, auf der Preisliste für Sonderabfall.,Bitte achten Sie bei dem Transport darauf, die Gebinde gut zu kennzeichnen und auf keinen Fall mit anderen Flüssigkeiten zu vermischen. Am sichersten transportieren Sie Sonderabfälle nur dicht verschlossen in den originalen Behältern (Gebinden) sowie aufrechtstehend (z.B. in einer Wanne, die Behälter aufrecht hält).,Wichtig: Nutzen Sie bitte die Abgabezeiten für Gewerbekunden (Mo. bis Do. von 7.00 – 14.00 Uhr und Fr. von 7.00 – 12.00 Uhr), wenn Sie größere Mengen an Sonderabfällen abgeben wollen.,Sachstand 19.07.2023 | E2: =VLOOKUP(A2,All!$C$2:$D$2424,2,FALSE) -> Bis zu 30 Kg (Gesamtmenge/ haushaltsübliche Mengen) Ihrer gefährlichen Abfälle täglich können Sie kostenlos auf den Wertstoffhöfen der Region Hannover oder der Deponie Hannover im Sonderabfallzwischenlager abgeben. Größere Mengen können Sie kostenpflichtig an der Sonderannahmestelle auf der Deponie Hannover abgeben. Bitte beachten Sie hierzu die Preisliste für Sonderabfall. Bitte achten Sie bei dem Transport darauf, die Gebinde gut zu kennzeichnen und auf keinen Fall mit anderen Flüssigkeiten zu vermischen. Am sichersten transportieren Sie Sonderabfälle nur dicht verschlossen in den originalen Behältern (Gebinden) sowie aufrecht stehend (z.B in einer Wanne, die Behälter aufrecht hält). | F2: =VLOOKUP(A2,All!$C$2:$F$2424,4,FALSE) -> Sonderabfall | G2: =VLOOKUP(A2,All!$C$2:$G$2424,5,FALSE) -> Wertstoffhof, Deponie | H2: =IF(D2=E2,"ok","no") -> no | I2: =IF(B2=F2,"ok","no") -> ok | J2: =IF(C2=G2,"ok","no") -> no
A3: Abdeckfolien | B3: Leichtverpackungen | C3: Wertstoffhof,Gelbe Tonne | D3: Abdeckfolien aus Kunststoff sind aus Polyethylen (PE). Saubere PE-Folien können wiederverwertet werden. Kleine Mengen nehmen die Wertstoffhöfe im Wertstoffsack an., , Größere Mengen aus Gewerbe oder Industrie werden ebenfalls von aha in Containern gesammelt. Wenden Sie sich an den Gewerbekundenservice von aha. | E3: =VLOOKUP(A3,All!$C$2:$D$2424,2,FALSE) -> Abdeckfolien aus Kunststoff sind aus Polyethylen (PE). Saubere PE-Folien können wiederverwertet werden. Kleine Mengen nehmen die Wertstoffhöfe im Wertstoffsack an. Größere Mengen aus Gewerbe oder Industrie werden ebenfalls von aha in Containern gesammelt. Wenden Sie sich an den Gewerbekundenservice von aha. | F3: =VLOOKUP(A3,All!$C$2:$F$2424,4,FALSE) -> Leichtverpackungen | G3: =VLOOKUP(A3,All!$C$2:$G$2424,5,FALSE) -> Wertstoffhof, Gelber Sack | H3: =IF(D3=E3,"ok","no") -> no | I3: =IF(B3=F3,"ok","no") -> ok | J3: =IF(C3=G3,"ok","no") -> no
A4: Abflussreiniger/Rohrreiniger | B4: Sonderabfall | C4: Wertstoffhof,Deponie Hannover - Sonderabfallannahmestelle | D4: Bis zu 30kg (Gesamtmenge/ haushaltsübliche Mengen) Ihrer gefährlichen Abfälle, können Sie täglich kostenlos auf allen Wertstoffhöfen abgeben. Auf den Wertstoffhöfen der Region werden Sonderabfälle in Gebinden bis zu einer Größe von max. 10 Litern entgegengenommen. Größere Mengen oder Gebinde können kostenpflichtig an der Sonderannahmestelle auf der Deponie Hannover Lahe abgeben. Gebinde über 10 Liter sind ebenfalls an der Deponie in Hannover anzuliefern.,Bitte beachten Sie die Mengenbegrenzung der einzelnen Abfälle, auf der Preisliste für Sonderabfall.,Bitte achten Sie bei dem Transport darauf, die Gebinde gut zu kennzeichnen und auf keinen Fall mit anderen Flüssigkeiten zu vermischen. Am sichersten transportieren Sie Sonderabfälle nur dicht verschlossen in den originalen Behältern (Gebinden) sowie aufrechtstehend (z.B. in einer Wanne, die Behälter aufrecht hält).,Wichtig: Nutzen Sie bitte die Abgabezeiten für Gewerbekunden (Mo. bis Do. von 7.00 – 14.00 Uhr und Fr. von 7.00 – 12.00 Uhr), wenn Sie größere Mengen an Sonderabfällen abgeben wollen.,Sachstand 19.07.2023 | E4: =VLOOKUP(A4,All!$C$2:$D$2424,2,FALSE) -> #N/A | F4: =VLOOKUP(A4,All!$C$2:$F$2424,4,FALSE) -> #N/A | G4: =VLOOKUP(A4,All!$C$2:$G$2424,5,FALSE) -> #N/A | H4: =IF(D4=E4,"ok","no") -> #N/A | I4: =IF(B4=F4,"ok","no") -> #N/A | J4: =IF(C4=G4,"ok","no") -> #N/A
A5: Abscheideranlage | B5: Sonderabfall | C5: Der Zweckverband Abfallwirtschaft Region Hannover (aha) | D5: aha entsorgt in der Region Hannover die Inhalte von Benzin- und Ölabscheidern und von Sand- und Schlammfängen. Im Auftrag von aha führt die Stadtentwässerung Hannover die Reinigung von Abscheideranlagen regionsweit aus., , Ansprechpartner bei der Stadtentwässerung Hannover sind Herr Münder und Herr Wagner, Tel: 0511 - 168 - 47440., , Bei Abwesenheit nimmt ein Anrufbeantworter die Anfragen auf., , , , Störungsmeldestelle der Stadtentwässerung, Tel: 0511 - 168 - 47377 tagsüber besetzt, oder Tel: 0511 - 168 - 47333, 24 Std. besetzt. | E5: =VLOOKUP(A5,All!$C$2:$D$2424,2,FALSE) -> aha entsorgt in der Region Hannover die Inhalte von Benzin- und Ölabscheidern und von Sand- und Schlammfängen. Im Auftrag von aha führt die Stadtentwässerung Hannover die Reinigung von Abscheideranlagen regionsweit aus. Ansprechpartner bei der Stadtentwässerung Hannover sind Herr Münder und Herr Wagner, Tel: 0511 - 168 - 47440. Bei Abwesenheit nimmt ein Anrufbeantworter die Anfragen auf. Störungsmeldestelle der Stadtentwässerung, Tel: 0511 - 168 - 47377 tagsüber besetzt, oder Tel: 0511 - 168 - 47333, 24 Std. besetzt. | F5: =VLOOKUP(A5,All!$C$2:$F$2424,4,FALSE) -> Sonderabfall | G5: =VLOOKUP(A5,All!$C$2:$G$2424,5,FALSE) -> Der Zweckverband Abfallwirtschaft Region Hannover (aha) | H5: =IF(D5=E5,"ok","no") -> no | I5: =IF(B5=F5,"ok","no") -> ok | J5: =IF(C5=G5,"ok","no") -> ok
A6: Abtönfarbe | B6: Sonderabfall,Restabfall,Wertstoff | C6: Wertstoffhof,Deponie Hannover - Sonderabfallannahmestelle | D6: Binderfarben sind wasserlöslich und zählen nicht zu den gefährlichen Abfällen, verursachen uneingedickt allerding böse Flecken. Eingetrocknete oder eingedickte (mit Sand, Gips oder Sägespäne vermischte Binderfarbe) können dem Restabfall über die Restabfalltonne zugeführt werden.,Flüssige Binderfarben geben Sie bitte an den Wertstoffhöfen der Region Hannover oder der Deponie Hannover im Sonderabfallzwischenlager ab.,Sachstand 07.05.2024 | E6: =VLOOKUP(A6,All!$C$2:$D$2424,2,FALSE) -> #N/A | F6: =VLOOKUP(A6,All!$C$2:$F$2424,4,FALSE) -> #N/A | G6: =VLOOKUP(A6,All!$C$2:$G$2424,5,FALSE) -> #N/A | H6: =IF(D6=E6,"ok","no") -> #N/A | I6: =IF(B6=F6,"ok","no") -> #N/A | J6: =IF(C6=G6,"ok","no") -> #N/A
A7: Aceton | B7: Sonderabfall | C7: Wertstoffhof,Deponie Hannover - Sonderabfallannahmestelle | D7: Bis zu 30kg (Gesamtmenge/ haushaltsübliche Mengen) Ihrer gefährlichen Abfälle, können Sie täglich kostenlos auf allen Wertstoffhöfen abgeben. Auf den Wertstoffhöfen der Region werden Sonderabfälle in Gebinden bis zu einer Größe von max. 10 Litern entgegengenommen. Größere Mengen oder Gebinde können kostenpflichtig an der Sonderannahmestelle auf der Deponie Hannover Lahe abgeben. Gebinde über 10 Liter sind ebenfalls an der Deponie in Hannover anzuliefern.,Bitte beachten Sie die Mengenbegrenzung der einzelnen Abfälle, auf der Preisliste für Sonderabfall.,Bitte achten Sie bei dem Transport darauf, die Gebinde gut zu kennzeichnen und auf keinen Fall mit anderen Flüssigkeiten zu vermischen. Am sichersten transportieren Sie Sonderabfälle nur dicht verschlossen in den originalen Behältern (Gebinden) sowie aufrechtstehend (z.B. in einer Wanne, die Behälter aufrecht hält).,Wichtig: Nutzen Sie bitte die Abgabezeiten für Gewerbekunden (Mo. bis Do. von 7.00 – 14.00 Uhr und Fr. von 7.00 – 12.00 Uhr), wenn Sie größere Mengen an Sonderabfällen abgeben wollen.,Sachstand 19.07.2023 | E7: =VLOOKUP(A7,All!$C$2:$D$2424,2,FALSE) -> Bis zu 30 Kg (Gesamtmenge/ haushaltsübliche Mengen) Ihrer gefährlichen Abfälle täglich können Sie kostenlos auf den Wertstoffhöfen der Region Hannover oder der Deponie Hannover im Sonderabfallzwischenlager abgeben. Größere Mengen können Sie kostenpflichtig an der Sonderannahmestelle auf der Deponie Hannover abgeben. Bitte beachten Sie hierzu die Preisliste für Sonderabfall. Bitte achten Sie bei dem Transport darauf, die Gebinde gut zu kennzeichnen und auf keinen Fall mit anderen Flüssigkeiten zu vermischen. Am sichersten transportieren Sie Sonderabfälle nur dicht verschlossen in den originalen Behältern (Gebinden) sowie aufrecht stehend (z.B in einer Wanne, die Behälter aufrecht hält). | F7: =VLOOKUP(A7,All!$C$2:$F$2424,4,FALSE) -> Sonderabfall | G7: =VLOOKUP(A7,All!$C$2:$G$2424,5,FALSE) -> Wertstoffhof, Deponie | H7: =IF(D7=E7,"ok","no") -> no | I7: =IF(B7=F7,"ok","no") -> ok | J7: =IF(C7=G7,"ok","no") -> no
A8: Acryl/ Silikon | B8: Sonderabfall | C8: Wertstoffhof,Deponie Hannover - Sonderabfallannahmestelle | D8: Bis zu 30kg (Gesamtmenge/ haushaltsübliche Mengen) Ihrer gefährlichen Abfälle, können Sie täglich kostenlos auf allen Wertstoffhöfen abgeben. Auf den Wertstoffhöfen der Region werden Sonderabfälle in Gebinden bis zu einer Größe von max. 10 Litern entgegengenommen. Größere Mengen oder Gebinde können kostenpflichtig an der Sonderannahmestelle auf der Deponie Hannover Lahe abgeben. Gebinde über 10 Liter sind ebenfalls an der Deponie in Hannover anzuliefern.,Bitte beachten Sie die Mengenbegrenzung der einzelnen Abfälle, auf der Preisliste für Sonderabfall.,Bitte achten Sie bei dem Transport darauf, die Gebinde gut zu kennzeichnen und auf keinen Fall mit anderen Flüssigkeiten zu vermischen. Am sichersten transportieren Sie Sonderabfälle nur dicht verschlossen in den originalen Behältern (Gebinden) sowie aufrechtstehend (z.B. in einer Wanne, die Behälter aufrecht hält).,Wichtig: Nutzen Sie bitte die Abgabezeiten für Gewerbekunden (Mo. bis Do. von 7.00 – 14.00 Uhr und Fr. von 7.00 – 12.00 Uhr), wenn Sie größere Mengen an Sonderabfällen abgeben wollen.,Sachstand 22.04.2024 | E8: =VLOOKUP(A8,All!$C$2:$D$2424,2,FALSE) -> #N/A | F8: =VLOOKUP(A8,All!$C$2:$F$2424,4,FALSE) -> #N/A | G8: =VLOOKUP(A8,All!$C$2:$G$2424,5,FALSE) -> #N/A | H8: =IF(D8=E8,"ok","no") -> #N/A | I8: =IF(B8=F8,"ok","no") -> #N/A | J8: =IF(C8=G8,"ok","no") -> #N/A
A9: Adventskranz | D9: Adventskränze müssen für die Entsorgung auf dem Komposthaufen oder in der Bioabfalltonne auseinandergenommen werden (das heißt Drahtgeflechte, Kerzen/ Kerzenhalter und alle Dekoration müssen entfernt werden.) Ganze Adventskränze können über die Restabfalltonne entsorgt werden.,Sachstand: 08.10.2024 | E9: =VLOOKUP(A9,All!$C$2:$D$2424,2,FALSE) -> #N/A | F9: =VLOOKUP(A9,All!$C$2:$F$2424,4,FALSE) -> #N/A | G9: =VLOOKUP(A9,All!$C$2:$G$2424,5,FALSE) -> #N/A | H9: =IF(D9=E9,"ok","no") -> #N/A | I9: =IF(B9=F9,"ok","no") -> #N/A | J9: =IF(C9=G9,"ok","no") -> #N/A
A10: Akkus | B10: Sonderabfall | C10: Wertstoffhof,Deponie Hannover - Sonderabfallannahmestelle | D10: aha nimmt Gerätebatterien, z. B. aus Taschenlampen, Uhren, Radios usw. an. Bis zu 30 kg Ihrer gefährlichen Abfälle täglich können Sie kostenlos auf den Wertstoffhöfen der Region Hannover oder der Deponie Hannover im Sonderabfallzwischenlager abgeben.,Ausgediente Akkus von E-Bikes und E-Scootern gehören zu laut §8 Batteriegesetz zu den Industriebatterien. Industriebatterien werden von aha nicht angenommen. Bitte geben Sie diese an den Fachhandel zurück.,Die einzige Ausnahme von dieser Regel stellen Starterbatterien auf Bleibasis von LKWs und PKWs sowie Motorrädern dar. | E10: =VLOOKUP(A10,All!$C$2:$D$2424,2,FALSE) -> #N/A | F10: =VLOOKUP(A10,All!$C$2:$F$2424,4,FALSE) -> #N/A | G10: =VLOOKUP(A10,All!$C$2:$G$2424,5,FALSE) -> #N/A | H10: =IF(D10=E10,"ok","no") -> #N/A | I10: =IF(B10=F10,"ok","no") -> #N/A | J10: =IF(C10=G10,"ok","no") -> #N/A
A11: Aktenordner | B11: Restabfall | C11: Restabfalltonne | D11: Alte Akten können (soweit es der Datenschutz es erfordert) durch spezielle Aktenvernichtungsfirmen entsorgt bzw. der Verwertung zugeführt werden. Aktendeckel aus Papier/Karton (unbeschichtet) gehören nur ohne Metallinlett in die Papiersammlung.,Komplette Ordner ohne Inhalt gehören in den Restabfallbehälter.,Sachstand:10.05.2024 | E11: =VLOOKUP(A11,All!$C$2:$D$2424,2,FALSE) -> #N/A | F11: =VLOOKUP(A11,All!$C$2:$F$2424,4,FALSE) -> #N/A | G11: =VLOOKUP(A11,All!$C$2:$G$2424,5,FALSE) -> #N/A | H11: =IF(D11=E11,"ok","no") -> #N/A | I11: =IF(B11=F11,"ok","no") -> #N/A | J11: =IF(C11=G11,"ok","no") -> #N/A
A12: Akustikpaneele | C12: Wertstoffhof,Deponie | D12: Bis zu 1m³ an Akustikpaneelen, die zur Schalldämmung verwendet werden, können kostenfrei auf den Wertstoffhöfen und Deponien über den Sperrabfallcontainer entsorgt werden. Größere Mengen werden kostenpflichtig auf den drei Regionsdeponien entgegengenommen.,5 m³ an Akustikpaneelen können Sie ebenfalls als Sperrabfall kostenlos direkt vor Ihrer Haustür abholen lassen. Dabei sollten die Gegenstände eine Länge von 2 m und ein Gewicht von max. 75 kg nicht überschreiten. Bitte vereinbaren Sie herfür einen Termin - online oder telefonisch.,Akustikplatten hingegen können leider weder auf den Deponien noch den Wertstoffhöfen entgegengenommen werden, da diese HBCD belastet sind. Ohne eine entsprechende Analyse kann allerdings nicht festgestellt werden, ob das Material belastet ist oder nicht.,Sachstand: 07.05.2024 | E12: =VLOOKUP(A12,All!$C$2:$D$2424,2,FALSE) -> #N/A | F12: =VLOOKUP(A12,All!$C$2:$F$2424,4,FALSE) -> #N/A | G12: =VLOOKUP(A12,All!$C$2:$G$2424,5,FALSE) -> #N/A | H12: =IF(D12=E12,"ok","no") -> #N/A | I12: =IF(B12=F12,"ok","no") -> #N/A | J12: =IF(C12=G12,"ok","no") -> #N/A
A13: Akustikplatten | D13: Akustikplatten werden weder auf den Deponien der Region noch auf den Wertstoffhöfen entgegengenommen, da diese oft HBCD belastet sind und diese Belastung ohne entsprechende Analyse nicht zu erkennen ist.,Bitte wenden Sie sich für die Entsorgung dieser an eine externe Firma aus dem Branchenbuch/-verzeichnis oder dem Internet.,Sachstand: 07.05.2024 | E13: =VLOOKUP(A13,All!$C$2:$D$2424,2,FALSE) -> #N/A | F13: =VLOOKUP(A13,All!$C$2:$F$2424,4,FALSE) -> #N/A | G13: =VLOOKUP(A13,All!$C$2:$G$2424,5,FALSE) -> #N/A | H13: =IF(D13=E13,"ok","no") -> #N/A | I13: =IF(B13=F13,"ok","no") -> #N/A | J13: =IF(C13=G13,"ok","no") -> #N/A
A14: Alleskleber | B14: Sonderabfall | C14: Wertstoffhof,Deponie Hannover - Sonderabfallannahmestelle | D14: Klebstoffe gehören zu den gefährlichen Abfällen (Sonderabfall). Bis zu 30 Kg (Gesamtmenge/ haushaltsübliche Mengen) Ihrer gefährlichen Abfälle täglich können Sie kostenlos auf den Wertstoffhöfen der Region Hannover oder der Deponie Hannover im Sonderabfallzwischenlager abgeben. Größere Mengen können Sie kostenpflichtig an der Sonderannahmestelle auf der Deponie Hannover abgeben. Bitte beachten Sie hierzu die Preisliste für Sonderabfall.,Bitte achten Sie bei dem Transport darauf, die Gebinde gut zu kennzeichnen und auf keinen Fall mit anderen Flüssigkeiten zu vermischen. Am sichersten transportieren Sie Sonderabfälle nur dicht verschlossen in den originalen Behältern (Gebinden) sowie aufrecht stehend (z.B in einer Wanne, die Behälter aufrecht hält).,Natürliche Klebstoffe, die aus pflanzlichen oder tierischen Produkten hergestellt werden, können über den Restabfall entsorgt werden. | E14: =VLOOKUP(A14,All!$C$2:$D$2424,2,FALSE) -> Klebstoffe gehören zu den gefährlichen Abfällen (Sonderabfall). Bis zu 30 Kg (Gesamtmenge/ haushaltsübliche Mengen) Ihrer gefährlichen Abfälle täglich können Sie kostenlos auf den Wertstoffhöfen der Region Hannover oder der Deponie Hannover im Sonderabfallzwischenlager abgeben. Größere Mengen können Sie kostenpflichtig an der Sonderannahmestelle auf der Deponie Hannover abgeben. Bitte beachten Sie hierzu die Preisliste für Sonderabfall. Bitte achten Sie bei dem Transport darauf, die Gebinde gut zu kennzeichnen und auf keinen Fall mit anderen Flüssigkeiten zu vermischen. Am sichersten transportieren Sie Sonderabfälle nur dicht verschlossen in den originalen Behältern (Gebinden) sowie aufrecht stehend (z.B in einer Wanne, die Behälter aufrecht hält). Natürliche Klebstoffe, die aus pflanzlichen oder tierischen Produkten hergestellt werden, können über den Restabfall entsorgt werden. | F14: =VLOOKUP(A14,All!$C$2:$F$2424,4,FALSE) -> Sonderabfall | G14: =VLOOKUP(A14,All!$C$2:$G$2424,5,FALSE) -> Wertstoffhof, Deponie | H14: =IF(D14=E14,"ok","no") -> no | I14: =IF(B14=F14,"ok","no") -> ok | J14: =IF(C14=G14,"ok","no") -> no
A15: Allzweckreiniger | B15: Sonderabfall | C15: Wertstoffhof,Deponie Hannover - Sonderabfallannahmestelle | D15: Bis zu 30kg (Gesamtmenge/ haushaltsübliche Mengen) Ihrer gefährlichen Abfälle, können Sie täglich kostenlos auf allen Wertstoffhöfen abgeben. Auf den Wertstoffhöfen der Region werden Sonderabfälle in Gebinden bis zu einer Größe von max. 10 Litern entgegengenommen. Größere Mengen oder Gebinde können kostenpflichtig an der Sonderannahmestelle auf der Deponie Hannover Lahe abgeben. Gebinde über 10 Liter sind ebenfalls an der Deponie in Hannover anzuliefern.,Bitte beachten Sie die Mengenbegrenzung der einzelnen Abfälle, auf der Preisliste für Sonderabfall.,Bitte achten Sie bei dem Transport darauf, die Gebinde gut zu kennzeichnen und auf keinen Fall mit anderen Flüssigkeiten zu vermischen. Am sichersten transportieren Sie Sonderabfälle nur dicht verschlossen in den originalen Behältern (Gebinden) sowie aufrechtstehend (z.B. in einer Wanne, die Behälter aufrecht hält).,Wichtig: Nutzen Sie bitte die Abgabezeiten für Gewerbekunden (Mo. bis Do. von 7.00 – 14.00 Uhr und Fr. von 7.00 – 12.00 Uhr), wenn Sie größere Mengen an Sonderabfällen abgeben wollen.,Sachstand 19.07.2023 | E15: =VLOOKUP(A15,All!$C$2:$D$2424,2,FALSE) -> Bis zu 30 Kg (Gesamtmenge/ haushaltsübliche Mengen) Ihrer gefährlichen Abfälle täglich können Sie kostenlos auf den Wertstoffhöfen der Region Hannover oder der Deponie Hannover im Sonderabfallzwischenlager abgeben. Größere Mengen können Sie kostenpflichtig an der Sonderannahmestelle auf der Deponie Hannover abgeben. Bitte beachten Sie hierzu die Preisliste für Sonderabfall. Bitte achten Sie bei dem Transport darauf, die Gebinde gut zu kennzeichnen und auf keinen Fall mit anderen Flüssigkeiten zu vermischen. Am sichersten transportieren Sie Sonderabfälle nur dicht verschlossen in den originalen Behältern (Gebinden) sowie aufrecht stehend (z.B in einer Wanne, die Behälter aufrecht hält). | F15: =VLOOKUP(A15,All!$C$2:$F$2424,4,FALSE) -> Sonderabfall | G15: =VLOOKUP(A15,All!$C$2:$G$2424,5,FALSE) -> Wertstoffhof, Deponie | H15: =IF(D15=E15,"ok","no") -> no | I15: =IF(B15=F15,"ok","no") -> ok | J15: =IF(C15=G15,"ok","no") -> no
A16: Altakten | D16: Alte Akten können (soweit es der Datenschutz erfordert) durch spezielle Aktenvernichtungsfirmen entsorgt bzw. verwertet werden. Aktendeckel aus Papier/Karton gehören - wenn sie unbeschichtet sind und das Metallinlett entfernt wurden - in die Papiersammlung.,Komplette Ordner können über den Restabfallbehälter entsorgt werden. | E16: =VLOOKUP(A16,All!$C$2:$D$2424,2,FALSE) -> #N/A | F16: =VLOOKUP(A16,All!$C$2:$F$2424,4,FALSE) -> #N/A | G16: =VLOOKUP(A16,All!$C$2:$G$2424,5,FALSE) -> #N/A | H16: =IF(D16=E16,"ok","no") -> #N/A | I16: =IF(B16=F16,"ok","no") -> #N/A | J16: =IF(C16=G16,"ok","no") -> #N/A
A17: Altauto | B17: Altfahrzeug | C17: Altfahrzeugverwertung | D17: Altfahrzeuge, Fahrzeugwracks, und Fahrzeugteile werden von zertifizierten Verwertungsbetrieben angenommen und einer Verwertung zugeführt (siehe www.gelbeseiten.de). Sie werden nicht an den Wertstoffhöfen von aha angenommen; auch bei der Sperrabfallsammlung werden sie nicht mitgenommen.,In zertifizierten Verwertungsbetrieben wird Ihnen ein Verwertungsnachweis für Ihr Altfahrzeug ausgehändigt; verlangen Sie diesen unbedingt!, In den Fachbetrieben werden aus diesen Fahrzeugen die Betriebsflüssigkeiten entfernt und einer fachgerechten Aufbereitung (z.B. Öle aller Art) oder Entsorgung zugeführt. Zusätzlich werden aus den Fahrzeugen die weiter einsetzbaren Ersatzteile demontiert und dem Markt zur weiteren Nutzung als kostengünstige Ersatzteile erhalten. Kabel, Metalle u.a. werden der Wiederverwertung zugeführt. Der nicht mehr nutzbare Rest des Fahrzeuges wird ordnungsgemäß entsorgt.,Über ,können Sie Fahrzeuge ohne Zulassung oder Fahrzeugwracks, die im öffentlichen Straßenraum stehen, melden.,Im Umland wenden Sie sich bitte an die entsprechende Stadt- oder Gemeindeverwaltung, bzw. an die Region Hannover.,Sachstand: 08.05.2024 | E17: =VLOOKUP(A17,All!$C$2:$D$2424,2,FALSE) -> Altfahrzeuge, Fahrzeugwracks, und Autoteile werden von zertifizierten Verwertungsbetrieben angenommen und einer Verwertung zugeführt (siehe ,). Sie werden nicht an den Wertstoffhöfen von aha angenommen; auch bei der Sperrabfallsammlung werden sie nicht mitgenommen. In zertifizierten Verwertungsbetrieben wird Ihnen ein Verwertungsnachweis für Ihr Altfahrzeug ausgehändigt; verlangen Sie diesen unbedingt!, In den Fachbetrieben werden aus diesen Fahrzeuge die Betriebsflüssigkeiten entfernt und einer fachgerechten Aufbereitung (z.B. Öle aller Art) oder Entsorgung zugeführt. Zusätzlich werden aus den Fahrzeugen die weiter einsetzbaren Ersatzteile demontiert und dem Markt zur weiteren Nutzung als kostengünstige Ersatzteile erhalten. Kabel, Metalle u.a. werden der Wiederverwertung zugeführt. Der nicht mehr nutzbare Rest des Fahrzeuges wird ordnungsgemäß entsorgt. Im Umland wenden Sie sich bitte an die entsprechende Stadt- oder Gemeindeverwaltung, bzw. an die Region Hannover. | F17: =VLOOKUP(A17,All!$C$2:$F$2424,4,FALSE) -> Altfahrzeug | G17: =VLOOKUP(A17,All!$C$2:$G$2424,5,FALSE) -> Altfahrzeugverwertung | H17: =IF(D17=E17,"ok","no") -> no | I17: =IF(B17=F17,"ok","no") -> ok | J17: =IF(C17=G17,"ok","no") -> ok
A18: Altfette/Speisefette/Fette | B18: Restabfall | C18: Restabfalltonne | D18: Erkaltete Fette/Öle sind als Restabfall zu entsorgen. Auch in kleinen Mengen gehören Fette und Öle nicht in den Abfluss. Größere Mengen, z. B. aus der Gastronomie, müssen über spezielle Entsorgungsunternehmen entsorgt werden oder wenden Sie sich an unseren Gewerbekundenservice., | E18: =VLOOKUP(A18,All!$C$2:$D$2424,2,FALSE) -> #N/A | F18: =VLOOKUP(A18,All!$C$2:$F$2424,4,FALSE) -> #N/A | G18: =VLOOKUP(A18,All!$C$2:$G$2424,5,FALSE) -> #N/A | H18: =IF(D18=E18,"ok","no") -> #N/A | I18: =IF(B18=F18,"ok","no") -> #N/A | J18: =IF(C18=G18,"ok","no") -> #N/A
A19: Altholz | C19: Wertstoffhof | D19: d.h. Holzabfälle ohne Störstoffe (keine Metalle, Kunststoffe, Glas), keine Holzabfälle mit schädlichen Verunreinigungen,und,z.B. Bahnschwellen, Leitungsmasten, Jägerzäune, Fenster, Außentüren und sonstige Hölzer aus dem Außenbereich (Annahme nur auf der Depoie Hannover in Lahe),Bis zu 1 m³ (Gesamtmenge/ haushaltsübliche Mengen) Ihrer Holzabfälle können Sie täglich kostenlos auf den Wertstoffhöfen der Region Hannover abgeben. Größere Mengen können Sie kostenpflichtig an den Deponien der Region Hannover abgeben. Bitte beachten Sie hierzu die Preisliste für die Deponieanlieferung. Die Annahmebedingungen unserer Deponien und Wertstoffhöfe finden Sie hier (,) und hier (,).,Verdreckte Holzabfälle aus Hühnerställen, Hühner-/ oder Taubenverschlägen werden auf Grund ihrer Verschmutzung durch Tierfäkalien weder auf den Wertstoffhöfen noch auf den drei Regionsdeponien angenommen. Bitte wenden Sie sich für die Entsorgung solcher Materialien an eine Fachfirma.,Sachstand: 13.03.2024, | E19: =VLOOKUP(A19,All!$C$2:$D$2424,2,FALSE) -> #N/A | F19: =VLOOKUP(A19,All!$C$2:$F$2424,4,FALSE) -> #N/A | G19: =VLOOKUP(A19,All!$C$2:$G$2424,5,FALSE) -> #N/A | H19: =IF(D19=E19,"ok","no") -> #N/A | I19: =IF(B19=F19,"ok","no") -> #N/A | J19: =IF(C19=G19,"ok","no") -> #N/A
